package edu.scu.coen160.lab4;

import java.util.*;
 
public class Lab4 {
    
	public static void exer1(){
        int denominator, numerator;
        numerator   = 4;
        denominator = 0;
        
        //excercise 1: this contains a divide by zero exception
        //we need to make sure denominator is initialized to a 
        //non-zero number
        //stack trace: java.lang.ArithmeticException
        System.out.println("Result: "+numerator / denominator);
        
        //this part was not printed w/ the exception
        System.out.println("exer1 - end."); 
    }
	
	public static void exer1_fix(){
        int denominator, numerator;
        numerator   = 4;
        denominator = 0;
        
        try {
        	System.out.println("Result: "+numerator / denominator);
		} catch (Exception e) {
			// TODO: handle exception
			System.err.println(e);
		}
        
        //now that we have a try catch block
        //this statement will print
        System.out.println("exer1 - end."); 
    }
	/*
	 * The first time I ran this, I entered 4
	 * The program output:
	 * 
	 * 		Enter an integer: 4
	 * 		The square of 4 is 16
	 * 		exer2 - end.
	 * 
	 * The ending statement did print
	 * 
	 * The second time runnin this code,
	 * I entered the string "oops"
	 * This was the output:
	 * 
	 * 		Enter an integer: oops
	 * 		Exception in thread "main" java.util.InputMismatchException
	 * 		at java.util.Scanner.throwFor(Scanner.java:864)
	 * 		at java.util.Scanner.next(Scanner.java:1485)
	 * 		at java.util.Scanner.nextInt(Scanner.java:2117)
	 *	 	at java.util.Scanner.nextInt(Scanner.java:2076)
	 * 		at edu.scu.coen160.lab4.Lab4.exer2(Lab4.java:85)
	 * 		at edu.scu.coen160.lab4.Lab4.main(Lab4.java:94)
	 * 
	 * The exer2-end statement did NOT print
	 */
	public static void exer2(){
	    Scanner scanner = new Scanner( System.in);
	    int num ;

	    System.out.print("Enter an integer: ");
	    num = scanner.nextInt();
	    // Squaring the number input
	    System.out.println("The square of " + num + " is " + num*num );
             
        System.out.println("exer2 - end."); 
	}
	
	/*
	 * Here I used a try catch around the scanner and squaring
	 * functions to ensure we are working with a valid input
	 * 
	 * This is the output: 
	 * 
	 * Enter an integer: oops
	 * java.util.InputMismatchException
	 * exer2 - end.
	 * 
	 * And exer2 - end printed
	 */
	public static void exer2_fix(){
	    Scanner scanner = new Scanner( System.in);
	    int num;

	    System.out.print("Enter an integer: ");
	    
	    try {
			num = scanner.nextInt();
			// Squaring the number input
		 	System.out.println("The square of " + num + " is " + num*num );

		} catch (Exception e) {
			// TODO: handle exception
			System.err.println(e);
		}
	   
        System.out.println("exer2 - end.");
        scanner.close();
	}
	
	public static void exer2_2(){
	    Scanner scanner = new Scanner( System.in);
	    int num;
	    Boolean error = false;

	    System.out.print("Enter an integer: ");
	    
	    try {
			num = scanner.nextInt();
			// Squaring the number input
		 	System.out.println("The square of " + num + " is " + num*num );

		} catch (Exception e) {
			// TODO: handle exception
			error = false;
		}
	   
        System.out.println("exer2 - end.");
        scanner.close();
	}

	public static void main(String[] args) {
//		//using try catch here still catches the exception thrown
//		//thrown in the function
//		try {
//			Lab4 .exer1();
//		} catch (Exception e) {
//			// TODO: handle exception
//			System.err.println(e);
//		}
		
		Lab4.exer2_2();
	}

}
